2025-06-07 20:14:10,142 - api.tasks - ERROR - tasks - process_sessions_data - 682 - ❌ Error processing session data for CONFER_NUM 52103 (Title: 제22대 제415회 제5차 국회본회의 (2024년 07월 03일)): connection already closed
2025-06-07 20:14:10,142 - api.tasks - ERROR - tasks - process_sessions_data - 685 - Full traceback for session processing error:
Traceback (most recent call last):
  File "/home/runner/workspace/.pythonlibs/lib/python3.12/site-packages/django/db/backends/postgresql/base.py", line 377, in _set_autocommit
    self.connection.autocommit = autocommit
    ^^^^^^^^^^^^^^^^^^^^^^^^^^
psycopg2.InterfaceError: connection already closed

The above exception was the direct cause of the following exception:

Traceback (most recent call last):
  File "/home/runner/workspace/backend/api/tasks.py", line 652, in process_sessions_data
    session_obj, created = Session.objects.update_or_create(
                           ^^^^^^^^^^^^^^^^^^^^^^^^^^^^^^^^^
  File "/home/runner/workspace/.pythonlibs/lib/python3.12/site-packages/django/db/models/manager.py", line 87, in manager_method
    return getattr(self.get_queryset(), name)(*args, **kwargs)
           ^^^^^^^^^^^^^^^^^^^^^^^^^^^^^^^^^^^^^^^^^^^^^^^^^^^
  File "/home/runner/workspace/.pythonlibs/lib/python3.12/site-packages/django/db/models/query.py", line 983, in update_or_create
    with transaction.atomic(using=self.db):
         ^^^^^^^^^^^^^^^^^^^^^^^^^^^^^^^^^
  File "/home/runner/workspace/.pythonlibs/lib/python3.12/site-packages/django/db/transaction.py", line 216, in __enter__
    connection.set_autocommit(
  File "/home/runner/workspace/.pythonlibs/lib/python3.12/site-packages/django/db/backends/base/base.py", line 483, in set_autocommit
    self._set_autocommit(autocommit)
  File "/home/runner/workspace/.pythonlibs/lib/python3.12/site-packages/django/db/backends/postgresql/base.py", line 376, in _set_autocommit
    with self.wrap_database_errors:
         ^^^^^^^^^^^^^^^^^^^^^^^^^
  File "/home/runner/workspace/.pythonlibs/lib/python3.12/site-packages/django/db/utils.py", line 91, in __exit__
    raise dj_exc_value.with_traceback(traceback) from exc_value
  File "/home/runner/workspace/.pythonlibs/lib/python3.12/site-packages/django/db/backends/postgresql/base.py", line 377, in _set_autocommit
    self.connection.autocommit = autocommit
    ^^^^^^^^^^^^^^^^^^^^^^^^^^
django.db.utils.InterfaceError: connection already closed