Starting data collection...
Traceback (most recent call last):
  File "/home/runner/workspace/.pythonlibs/lib/python3.12/site-packages/kombu/utils/functional.py", line 32, in __call__
    return self.__value__
           ^^^^^^^^^^^^^^
AttributeError: 'ChannelPromise' object has no attribute '__value__'. Did you mean: '__call__'?

During handling of the above exception, another exception occurred:

Traceback (most recent call last):
  File "/home/runner/workspace/.pythonlibs/lib/python3.12/site-packages/kombu/connection.py", line 472, in _reraise_as_library_errors
    yield
  File "/home/runner/workspace/.pythonlibs/lib/python3.12/site-packages/kombu/connection.py", line 459, in _ensure_connection
    return retry_over_time(
           ^^^^^^^^^^^^^^^^
  File "/home/runner/workspace/.pythonlibs/lib/python3.12/site-packages/kombu/utils/functional.py", line 318, in retry_over_time
    return fun(*args, **kwargs)
           ^^^^^^^^^^^^^^^^^^^^
  File "/home/runner/workspace/.pythonlibs/lib/python3.12/site-packages/kombu/connection.py", line 938, in _connection_factory
    self._connection = self._establish_connection()
                       ^^^^^^^^^^^^^^^^^^^^^^^^^^^^
  File "/home/runner/workspace/.pythonlibs/lib/python3.12/site-packages/kombu/connection.py", line 860, in _establish_connection
    conn = self.transport.establish_connection()
           ^^^^^^^^^^^^^^^^^^^^^^^^^^^^^^^^^^^^^
  File "/home/runner/workspace/.pythonlibs/lib/python3.12/site-packages/kombu/transport/pyamqp.py", line 203, in establish_connection
    conn.connect()
  File "/home/runner/workspace/.pythonlibs/lib/python3.12/site-packages/amqp/connection.py", line 324, in connect
    self.transport.connect()
  File "/home/runner/workspace/.pythonlibs/lib/python3.12/site-packages/amqp/transport.py", line 132, in connect
    self._connect(self.host, self.port, self.connect_timeout)
  File "/home/runner/workspace/.pythonlibs/lib/python3.12/site-packages/amqp/transport.py", line 187, in _connect
    self.sock.connect(sa)
ConnectionRefusedError: [Errno 111] Connection refused

The above exception was the direct cause of the following exception:

Traceback (most recent call last):
  File "/home/runner/workspace/backend/manage.py", line 22, in <module>
    main()
  File "/home/runner/workspace/backend/manage.py", line 18, in main
    execute_from_command_line(sys.argv)
  File "/home/runner/workspace/.pythonlibs/lib/python3.12/site-packages/django/core/management/__init__.py", line 442, in execute_from_command_line
    utility.execute()
  File "/home/runner/workspace/.pythonlibs/lib/python3.12/site-packages/django/core/management/__init__.py", line 436, in execute
    self.fetch_command(subcommand).run_from_argv(self.argv)
  File "/home/runner/workspace/.pythonlibs/lib/python3.12/site-packages/django/core/management/base.py", line 413, in run_from_argv
    self.execute(*args, **cmd_options)
  File "/home/runner/workspace/.pythonlibs/lib/python3.12/site-packages/django/core/management/base.py", line 459, in execute
    output = self.handle(*args, **options)
             ^^^^^^^^^^^^^^^^^^^^^^^^^^^^^
  File "/home/runner/workspace/backend/api/management/commands/start_collection.py", line 12, in handle
    fetch_latest_sessions.delay()
  File "/home/runner/workspace/.pythonlibs/lib/python3.12/site-packages/celery/app/task.py", line 444, in delay
    return self.apply_async(args, kwargs)
           ^^^^^^^^^^^^^^^^^^^^^^^^^^^^^^
  File "/home/runner/workspace/.pythonlibs/lib/python3.12/site-packages/celery/app/task.py", line 594, in apply_async
    return app.send_task(
           ^^^^^^^^^^^^^^
  File "/home/runner/workspace/.pythonlibs/lib/python3.12/site-packages/celery/app/base.py", line 799, in send_task
    amqp.send_task_message(P, name, message, **options)
  File "/home/runner/workspace/.pythonlibs/lib/python3.12/site-packages/celery/app/amqp.py", line 518, in send_task_message
    ret = producer.publish(
          ^^^^^^^^^^^^^^^^^
  File "/home/runner/workspace/.pythonlibs/lib/python3.12/site-packages/kombu/messaging.py", line 190, in publish
    return _publish(
           ^^^^^^^^^
  File "/home/runner/workspace/.pythonlibs/lib/python3.12/site-packages/kombu/connection.py", line 556, in _ensured
    return fun(*args, **kwargs)
           ^^^^^^^^^^^^^^^^^^^^
  File "/home/runner/workspace/.pythonlibs/lib/python3.12/site-packages/kombu/messaging.py", line 200, in _publish
    channel = self.channel
              ^^^^^^^^^^^^
  File "/home/runner/workspace/.pythonlibs/lib/python3.12/site-packages/kombu/messaging.py", line 224, in _get_channel
    channel = self._channel = channel()
                              ^^^^^^^^^
  File "/home/runner/workspace/.pythonlibs/lib/python3.12/site-packages/kombu/utils/functional.py", line 34, in __call__
    value = self.__value__ = self.__contract__()
                             ^^^^^^^^^^^^^^^^^^^
  File "/home/runner/workspace/.pythonlibs/lib/python3.12/site-packages/kombu/messaging.py", line 240, in <lambda>
    channel = ChannelPromise(lambda: connection.default_channel)
                                     ^^^^^^^^^^^^^^^^^^^^^^^^^^
  File "/home/runner/workspace/.pythonlibs/lib/python3.12/site-packages/kombu/connection.py", line 957, in default_channel
    self._ensure_connection(**conn_opts)
  File "/home/runner/workspace/.pythonlibs/lib/python3.12/site-packages/kombu/connection.py", line 458, in _ensure_connection
    with ctx():
         ^^^^^
  File "/nix/store/nb21sc3npfc8gvazwnrjxpvb5d48jysx-python3-3.12.7/lib/python3.12/contextlib.py", line 158, in __exit__
    self.gen.throw(value)
  File "/home/runner/workspace/.pythonlibs/lib/python3.12/site-packages/kombu/connection.py", line 476, in _reraise_as_library_errors
    raise ConnectionError(str(exc)) from exc
kombu.exceptions.OperationalError: [Errno 111] Connection refused